<?xml version="1.0" encoding="UTF-8"?>
<sdf version='1.9'>
  <model name='x500_base'>
    <pose>0 0 .24 0 0 0</pose>
    <self_collide>false</self_collide>
    <static>false</static>
    
    <link name="base_link">
      <inertial>
        <mass>2.0</mass>
        <inertia>
          <ixx>0.02166666666666667</ixx>
          <ixy>0</ixy>
          <ixz>0</ixz>
          <iyy>0.02166666666666667</iyy>
          <iyz>0</iyz>
          <izz>0.04000000000000001</izz>
        </inertia>
      </inertial>
      <gravity>true</gravity>
      <velocity_decay />
      
      <visual name="base_link_visual">
        <pose>0 0 .025 0 0 3.141592654</pose>
        <geometry>
          <mesh>
            <scale>1 1 1</scale>
            <uri>model://x500_base/meshes/NXP-HGD-CF.dae</uri>
          </mesh>
        </geometry>
        <material>
          <ambient>0.22 0.28 0.20 1</ambient>
          <diffuse>0.22 0.28 0.20 1</diffuse>
          <specular>0.05 0.05 0.05 1</specular>
          <pbr>
            <metal>
              <roughness>0.9</roughness>
              <metalness>0.1</metalness>
            </metal>
          </pbr>
        </material>
      </visual>

      <visual name="napoli_logo">
        <pose>0 0 0.06 0 0 0</pose>
        <cast_shadows>false</cast_shadows>
        <geometry>
          <plane>
            <normal>0 0 1</normal>
            <size>0.12 0.12</size>
          </plane>
        </geometry>
        <material>
          <ambient>1 1 1 1</ambient>
          <diffuse>1 1 1 1</diffuse>
          <specular>0.2 0.2 0.2 1</specular>
          <pbr>
            <metal>
              <albedo_map>model://x500_base/materials/textures/napoli.png</albedo_map>
              <roughness>0.5</roughness>
              <metalness>0.0</metalness>
            </metal>
          </pbr>
        </material>
      </visual>

      <visual name="5010_motor_base_0">
        <pose>0.174 0.174 .032 0 0 -.45</pose>
        <geometry><mesh><scale>1 1 1</scale><uri>model://x500_base/meshes/5010Base.dae</uri></mesh></geometry>
        <material><ambient>0.1 0.1 0.1 1</ambient><diffuse>0.1 0.1 0.1 1</diffuse></material>
      </visual>
      <visual name="5010_motor_base_1">
        <pose>-0.174 0.174 .032 0 0 -.45</pose>
        <geometry><mesh><scale>1 1 1</scale><uri>model://x500_base/meshes/5010Base.dae</uri></mesh></geometry>
        <material><ambient>0.1 0.1 0.1 1</ambient><diffuse>0.1 0.1 0.1 1</diffuse></material>
      </visual>
      <visual name="5010_motor_base_2">
        <pose>0.174 -0.174 .032 0 0 -.45</pose>
        <geometry><mesh><scale>1 1 1</scale><uri>model://x500_base/meshes/5010Base.dae</uri></mesh></geometry>
        <material><ambient>0.1 0.1 0.1 1</ambient><diffuse>0.1 0.1 0.1 1</diffuse></material>
      </visual>
      <visual name="5010_motor_base_3">
        <pose>-0.174 -0.174 .032 0 0 -.45</pose>
        <geometry><mesh><scale>1 1 1</scale><uri>model://x500_base/meshes/5010Base.dae</uri></mesh></geometry>
        <material><ambient>0.1 0.1 0.1 1</ambient><diffuse>0.1 0.1 0.1 1</diffuse></material>
      </visual>

      <visual name="NXP_FMUK66_FRONT">
        <pose>0.047 .001 .043 1 0 1.57</pose>
        <cast_shadows>false</cast_shadows>
        <geometry><plane><normal>0 0 1</normal><size>.013 .007</size></plane></geometry>
        <material><ambient>0.05 0.05 0.05 1</ambient><diffuse>0.05 0.05 0.05 1</diffuse></material>
      </visual>
      <visual name="NXP_FMUK66_TOP">
        <pose>-0.023 0 .0515 0 0 -1.57</pose>
        <cast_shadows>false</cast_shadows>
        <geometry><plane><normal>0 0 1</normal><size>.013 .007</size></plane></geometry>
        <material><ambient>0.05 0.05 0.05 1</ambient><diffuse>0.05 0.05 0.05 1</diffuse></material>
      </visual>
      <visual name="RDDRONE_FMUK66_TOP">
        <pose>-.03 0 .0515 0 0 -1.57</pose>
        <cast_shadows>false</cast_shadows>
        <geometry><plane><normal>0 0 1</normal><size>.032 .0034</size></plane></geometry>
        <material><ambient>0.05 0.05 0.05 1</ambient><diffuse>0.05 0.05 0.05 1</diffuse></material>
      </visual>

      <collision name="base_link_collision_0">
        <pose>0 0 .007 0 0 0</pose>
        <geometry><box><size>0.35 0.35 0.05</size></box></geometry>
      </collision>
      <collision name="base_link_collision_1">
        <pose>0 -0.098 -.123 -0.35 0 0</pose>
        <geometry><box><size>0.015 0.015 0.21</size></box></geometry>
      </collision>
      <collision name="base_link_collision_2">
        <pose>0 0.098 -.123 0.35 0 0</pose>
        <geometry><box><size>0.015 0.015 0.21</size></box></geometry>
      </collision>
      <collision name="base_link_collision_3">
        <pose>0 -0.132 -.2195 0 0 0</pose>
        <geometry><box><size>0.25 0.015 0.015</size></box></geometry>
      </collision>
      <collision name="base_link_collision_4">
        <pose>0 0.132 -.2195 0 0 0</pose>
        <geometry><box><size>0.25 0.015 0.015</size></box></geometry>
      </collision>

      <sensor name="air_pressure_sensor" type="air_pressure">
        <gz_frame_id>base_link</gz_frame_id>
        <always_on>1</always_on>
        <update_rate>50</update_rate>
        <air_pressure>
          <pressure>
            <noise type="gaussian"><mean>0</mean><stddev>3</stddev></noise>
          </pressure>
        </air_pressure>
      </sensor>
      <sensor name="magnetometer_sensor" type="magnetometer">
        <gz_frame_id>base_link</gz_frame_id>
        <always_on>1</always_on>
        <update_rate>100</update_rate>
        <magnetometer>
          <x><noise type="gaussian"><stddev>0.0001</stddev></noise></x>
          <y><noise type="gaussian"><stddev>0.0001</stddev></noise></y>
          <z><noise type="gaussian"><stddev>0.0001</stddev></noise></z>
        </magnetometer>
      </sensor>
      <sensor name="imu_sensor" type="imu">
        <gz_frame_id>base_link</gz_frame_id>
        <always_on>1</always_on>
        <update_rate>250</update_rate>
        <imu>
          <angular_velocity>
            <x><noise type="gaussian"><stddev>0.00087</stddev></noise></x>
            <y><noise type="gaussian"><stddev>0.00087</stddev></noise></y>
            <z><noise type="gaussian"><stddev>0.00087</stddev></noise></z>
          </angular_velocity>
          <linear_acceleration>
            <x><noise type="gaussian"><stddev>0.00637</stddev></noise></x>
            <y><noise type="gaussian"><stddev>0.00637</stddev></noise></y>
            <z><noise type="gaussian"><stddev>0.00686</stddev></noise></z>
          </linear_acceleration>
        </imu>
      </sensor>
      <sensor name="navsat_sensor" type="navsat">
        <gz_frame_id>base_link</gz_frame_id>
        <always_on>1</always_on>
        <update_rate>30</update_rate>
      </sensor>

      <sensor name="downward_camera" type="camera">
        <pose>0 0 -0.05 0 1.5708 0</pose>
        <camera>
          <horizontal_fov>1.047</horizontal_fov>
          <image>
            <width>640</width>
            <height>480</height>
          </image>
          <clip>
            <near>0.1</near>
            <far>100</far>
          </clip>
        </camera>
        <always_on>1</always_on>
        <update_rate>30</update_rate>
        <visualize>true</visualize>
        <topic>/drone/downward_cam/image_raw</topic>
      </sensor>

    </link>

    <link name="rotor_0">
      <gravity>true</gravity>
      <self_collide>false</self_collide>
      <velocity_decay />
      <pose>0.174 -0.174 0.06 0 0 0</pose>
      <inertial>
        <mass>0.016</mass>
        <inertia><ixx>3.8e-07</ixx><iyy>2.6e-05</iyy><izz>2.6e-05</izz></inertia>
      </inertial>
      <visual name="rotor_0_visual">
        <pose>-0.022 -0.146 -0.016 0 0 0</pose>
        <geometry><mesh><scale>0.85 0.85 0.85</scale><uri>model://x500_base/meshes/1345_prop_ccw.stl</uri></mesh></geometry>
        <material><ambient>0.05 0.05 0.05 1</ambient><diffuse>0.05 0.05 0.05 1</diffuse></material>
      </visual>
      <visual name="rotor_0_visual_motor_bell">
        <pose>0 0 -.032 0 0 0</pose>
        <geometry><mesh><scale>1 1 1</scale><uri>model://x500_base/meshes/5010Bell.dae</uri></mesh></geometry>
        <material><ambient>0.1 0.1 0.1 1</ambient><diffuse>0.1 0.1 0.1 1</diffuse></material>
      </visual>
      <collision name="rotor_0_collision">
        <pose>0 0 0 0 0 0 </pose>
        <geometry><box><size>0.279 0.017 0.001</size></box></geometry>
      </collision>
    </link>
    <joint name="rotor_0_joint" type="revolute">
      <parent>base_link</parent>
      <child>rotor_0</child>
      <axis><xyz>0 0 1</xyz><limit><lower>-1e+16</lower><upper>1e+16</upper></limit></axis>
    </joint>

    <link name="rotor_1">
      <gravity>true</gravity>
      <self_collide>false</self_collide>
      <pose>-0.174 0.174 0.06 0 0 0</pose>
      <inertial>
        <mass>0.016</mass>
        <inertia><ixx>3.8e-07</ixx><iyy>2.6e-05</iyy><izz>2.6e-05</izz></inertia>
      </inertial>
      <visual name="rotor_1_visual">
        <pose>-0.022 -0.146 -0.016 0 0 0</pose>
        <geometry><mesh><scale>0.85 0.85 0.85</scale><uri>model://x500_base/meshes/1345_prop_ccw.stl</uri></mesh></geometry>
        <material><ambient>0.05 0.05 0.05 1</ambient><diffuse>0.05 0.05 0.05 1</diffuse></material>
      </visual>
      <visual name="rotor_1_visual_motor_top">
        <pose>0 0 -.032 0 0 0</pose>
        <geometry><mesh><scale>1 1 1</scale><uri>model://x500_base/meshes/5010Bell.dae</uri></mesh></geometry>
        <material><ambient>0.1 0.1 0.1 1</ambient><diffuse>0.1 0.1 0.1 1</diffuse></material>
      </visual>
      <collision name="rotor_1_collision">
        <pose>0 0 0 0 0 0 </pose>
        <geometry><box><size>0.279 0.017 0.001</size></box></geometry>
      </collision>
    </link>
    <joint name="rotor_1_joint" type="revolute">
      <parent>base_link</parent>
      <child>rotor_1</child>
      <axis><xyz>0 0 1</xyz><limit><lower>-1e+16</lower><upper>1e+16</upper></limit></axis>
    </joint>

    <link name="rotor_2">
      <gravity>true</gravity>
      <self_collide>false</self_collide>
      <pose>0.174 0.174 0.06 0 0 0</pose>
      <inertial>
        <mass>0.016</mass>
        <inertia><ixx>3.8e-07</ixx><iyy>2.6e-05</iyy><izz>2.6e-05</izz></inertia>
      </inertial>
      <visual name="rotor_2_visual">
        <pose>-0.022 -0.146 -0.016 0 0 0</pose>
        <geometry><mesh><scale>0.85 0.85 0.85</scale><uri>model://x500_base/meshes/1345_prop_cw.stl</uri></mesh></geometry>
        <material><ambient>0.05 0.05 0.05 1</ambient><diffuse>0.05 0.05 0.05 1</diffuse></material>
      </visual>
      <visual name="rotor_2_visual_motor_top">
        <pose>0 0 -.032 0 0 0</pose>
        <geometry><mesh><scale>1 1 1</scale><uri>model://x500_base/meshes/5010Bell.dae</uri></mesh></geometry>
        <material><ambient>0.1 0.1 0.1 1</ambient><diffuse>0.1 0.1 0.1 1</diffuse></material>
      </visual>
      <collision name="rotor_2_collision">
        <pose>0 0 0 0 0 0 </pose>
        <geometry><box><size>0.279 0.017 0.001</size></box></geometry>
      </collision>
    </link>
    <joint name="rotor_2_joint" type="revolute">
      <parent>base_link</parent>
      <child>rotor_2</child>
      <axis><xyz>0 0 1</xyz><limit><lower>-1e+16</lower><upper>1e+16</upper></limit></axis>
    </joint>

    <link name="rotor_3">
      <gravity>true</gravity>
      <self_collide>false</self_collide>
      <pose>-0.174 -0.174 0.06 0 0 0</pose>
      <inertial>
        <mass>0.016</mass>
        <inertia><ixx>3.8e-07</ixx><iyy>2.6e-05</iyy><izz>2.6e-05</izz></inertia>
      </inertial>
      <visual name="rotor_3_visual">
        <pose>-0.022 -0.146 -0.016 0 0 0</pose>
        <geometry><mesh><scale>0.85 0.85 0.85</scale><uri>model://x500_base/meshes/1345_prop_cw.stl</uri></mesh></geometry>
        <material><ambient>0.05 0.05 0.05 1</ambient><diffuse>0.05 0.05 0.05 1</diffuse></material>
      </visual>
      <visual name="rotor_3_visual_motor_top">
        <pose>0 0 -.032 0 0 0</pose>
        <geometry><mesh><scale>1 1 1</scale><uri>model://x500_base/meshes/5010Bell.dae</uri></mesh></geometry>
        <material><ambient>0.1 0.1 0.1 1</ambient><diffuse>0.1 0.1 0.1 1</diffuse></material>
      </visual>
      <collision name="rotor_3_collision">
        <pose>0 0 0 0 0 0 </pose>
        <geometry><box><size>0.279 0.017 0.001</size></box></geometry>
      </collision>
    </link>
    <joint name="rotor_3_joint" type="revolute">
      <parent>base_link</parent>
      <child>rotor_3</child>
      <axis><xyz>0 0 1</xyz><limit><lower>-1e+16</lower><upper>1e+16</upper></limit></axis>
    </joint>

  </model>
</sdf>
